import React from 'react';
import { vi } from 'vitest';
import { render, screen, waitFor } from '@testing-library/react';
import userEvent from '@testing-library/user-event';
import ErrorBoundary from './ErrorBoundary';

// Suppress console.error for error boundary tests
const originalError = console.error;
beforeAll(() => {
  console.error = vi.fn();
});

afterAll(() => {
  console.error = originalError;
});

// Component that throws an error when shouldThrow is true
const ThrowError = ({ shouldThrow }: { shouldThrow: boolean }) => {
  if (shouldThrow) {
    throw new Error('Test error');
  }
  return <div>No error</div>;
};

describe('ErrorBoundary', () => {
  it('renders children when there is no error', () => {
    render(
      <ErrorBoundary>
        <div>Test content</div>
      </ErrorBoundary>
    );

    expect(screen.getByText('Test content')).toBeInTheDocument();
  });

  it('renders error UI when there is an error', () => {
    render(
      <ErrorBoundary>
        <ThrowError shouldThrow={true} />
      </ErrorBoundary>
    );

    expect(screen.getByText('Oops! Something went wrong')).toBeInTheDocument();
    expect(screen.getByRole('button', { name: /try again/i })).toBeInTheDocument();
    expect(screen.getByRole('button', { name: /reload page/i })).toBeInTheDocument();
  });

  it('renders custom fallback when provided', () => {
    const customFallback = <div>Custom error message</div>;
    
    render(
      <ErrorBoundary fallback={customFallback}>
        <ThrowError shouldThrow={true} />
      </ErrorBoundary>
    );

    expect(screen.getByText('Custom error message')).toBeInTheDocument();
    expect(screen.queryByText('Oops! Something went wrong')).not.toBeInTheDocument();
  });

  it('resets error state when Try Again is clicked', async () => {
    const TestComponent = () => {
      const [shouldThrow, setShouldThrow] = React.useState(true);
      
      return (
        <ErrorBoundary>
          <button onClick={() => setShouldThrow(false)}>Reset</button>
          <ThrowError shouldThrow={shouldThrow} />
        </ErrorBoundary>
      );
    };

    render(<TestComponent />);

    // Error should be shown initially
    expect(screen.getByText('Oops! Something went wrong')).toBeInTheDocument();

    const user = userEvent.setup();
    const tryAgainButton = screen.getByRole('button', { name: /try again/i });
    
    await user.click(tryAgainButton);

    // After clicking Try Again, the error boundary should reset
    // but since our test component still throws, it will show error again
    // This is the expected behavior for error boundaries
    await waitFor(() => {
      expect(screen.getByText('Oops! Something went wrong')).toBeInTheDocument();
    });
  });

  it('reloads page when Reload Page is clicked', async () => {
    // Mock window.location.reload
    const mockReload = vi.fn();
    Object.defineProperty(window, 'location', {
      value: { reload: mockReload },
      writable: true,
    });

    render(
      <ErrorBoundary>
        <ThrowError shouldThrow={true} />
      </ErrorBoundary>
    );

    const user = userEvent.setup();
    const reloadButton = screen.getByRole('button', { name: /reload page/i });
    
    await user.click(reloadButton);

    expect(mockReload).toHaveBeenCalled();
  });
});